Workbook

Sheet Preteky_2027
A1: ID | B1: Date | C1: Year | D1: Month | E1: Start Time | F1: Month_Number | G1: Race | H1: Location | I1: Type | J1: Distance_km | K1: Priority | L1: Status | M1: Target | N1: Registration | O1: Final_Time | P1: Place | Q1: Days_Gap | R1: Note | S1: Phase | T1: Week_Gap
A2: 1 | B2: 46495 | C2: =IF(B2="","",YEAR(B2)) -> 2027 | D2: =IF(B2="","",CHOOSE(MONTH(B2),"Január","Február","Marec","Apríl","Máj","Jún","Júl","August","September","Október","November","December")) -> Apríl | E2: 0.41666667 | F2: =IF(B2="","",MONTH(B2)) -> 4 | G2: Generali 1/2Maraton Praha 2027 | H2: Praha | I2: Cesta | J2: 21 | K2: A | L2: Plánujem | M2: Sub 02:00 | N2: Nie | Q2: ="" | R2: prvý test sezóny | S2: =IF(B2="","",IF(L2="Absolvovaný","Absolvovaný",IF(L2="Zrušený","Zrušený","Plánovaný"))) -> Plánovaný | T2: =IF(Q2="","",Q2/7)
A3: 2 | B3: 46557 | C3: =IF(B3="","",YEAR(B3)) -> 2027 | D3: =IF(B3="","",CHOOSE(MONTH(B3),"Január","Február","Marec","Apríl","Máj","Jún","Júl","August","September","Október","November","December")) -> Jún | E3: 0.75 | F3: =IF(B3="","",MONTH(B3)) -> 6 | G3: G-Schock Runday Trávnica | H3: Trávnica | I3: Trail | J3: 8 | K3: B | L3: Plánujem | M3: pod 1:50 | N3: Nie | Q3: =IF(OR(B3="",B2=""),"",B3-B2) -> 62 | R3: kopcovitý profil | S3: =IF(B3="","",IF(L3="Absolvovaný","Absolvovaný",IF(L3="Zrušený","Zrušený","Plánovaný"))) -> Plánovaný | T3: =IF(Q3="","",Q3/7) -> 8.8571429
A4: 3 | B4: 46663 | C4: =IF(B4="","",YEAR(B4)) -> 2027 | D4: =IF(B4="","",CHOOSE(MONTH(B4),"Január","Február","Marec","Apríl","Máj","Jún","Júl","August","September","Október","November","December")) -> Október | E4: 0.375 | F4: =IF(B4="","",MONTH(B4)) -> 10 | G4: Košice Peace Marathon | H4: Košice | I4: Cesta | J4: 42 | K4: A | L4: Plánujem | M4: Sub 04:00 | N4: Nie | Q4: =IF(OR(B4="",B3=""),"",B4-B3) -> 106 | S4: =IF(B4="","",IF(L4="Absolvovaný","Absolvovaný",IF(L4="Zrušený","Zrušený","Plánovaný"))) -> Plánovaný | T4: =IF(Q4="","",Q4/7) -> 15.142857
C5: =IF(B5="","",YEAR(B5)) | D5: =IF(B5="","",CHOOSE(MONTH(B5),"Január","Február","Marec","Apríl","Máj","Jún","Júl","August","September","Október","November","December")) | F5: =IF(B5="","",MONTH(B5)) | Q5: =IF(OR(B5="",B4=""),"",B5-B4) | S5: =IF(B5="","",IF(L5="Absolvovaný","Absolvovaný",IF(L5="Zrušený","Zrušený","Plánovaný"))) | T5: =IF(Q5="","",Q5/7)
C6: =IF(B6="","",YEAR(B6)) | D6: =IF(B6="","",CHOOSE(MONTH(B6),"Január","Február","Marec","Apríl","Máj","Jún","Júl","August","September","Október","November","December")) | F6: =IF(B6="","",MONTH(B6)) | Q6: =IF(OR(B6="",B5=""),"",B6-B5) | S6: =IF(B6="","",IF(L6="Absolvovaný","Absolvovaný",IF(L6="Zrušený","Zrušený","Plánovaný"))) | T6: =IF(Q6="","",Q6/7)
C7: =IF(B7="","",YEAR(B7)) | D7: =IF(B7="","",CHOOSE(MONTH(B7),"Január","Február","Marec","Apríl","Máj","Jún","Júl","August","September","Október","November","December")) | F7: =IF(B7="","",MONTH(B7)) | Q7: =IF(OR(B7="",B6=""),"",B7-B6) | S7: =IF(B7="","",IF(L7="Absolvovaný","Absolvovaný",IF(L7="Zrušený","Zrušený","Plánovaný"))) | T7: =IF(Q7="","",Q7/7)
C8: =IF(B8="","",YEAR(B8)) | D8: =IF(B8="","",CHOOSE(MONTH(B8),"Január","Február","Marec","Apríl","Máj","Jún","Júl","August","September","Október","November","December")) | F8: =IF(B8="","",MONTH(B8)) | Q8: =IF(OR(B8="",B7=""),"",B8-B7) | S8: =IF(B8="","",IF(L8="Absolvovaný","Absolvovaný",IF(L8="Zrušený","Zrušený","Plánovaný"))) | T8: =IF(Q8="","",Q8/7)
C9: =IF(B9="","",YEAR(B9)) | D9: =IF(B9="","",CHOOSE(MONTH(B9),"Január","Február","Marec","Apríl","Máj","Jún","Júl","August","September","Október","November","December")) | F9: =IF(B9="","",MONTH(B9)) | Q9: =IF(OR(B9="",B8=""),"",B9-B8) | S9: =IF(B9="","",IF(L9="Absolvovaný","Absolvovaný",IF(L9="Zrušený","Zrušený","Plánovaný"))) | T9: =IF(Q9="","",Q9/7)
C10: =IF(B10="","",YEAR(B10)) | D10: =IF(B10="","",CHOOSE(MONTH(B10),"Január","Február","Marec","Apríl","Máj","Jún","Júl","August","September","Október","November","December")) | F10: =IF(B10="","",MONTH(B10)) | Q10: =IF(OR(B10="",B9=""),"",B10-B9) | S10: =IF(B10="","",IF(L10="Absolvovaný","Absolvovaný",IF(L10="Zrušený","Zrušený","Plánovaný"))) | T10: =IF(Q10="","",Q10/7)
C11: =IF(B11="","",YEAR(B11)) | D11: =IF(B11="","",CHOOSE(MONTH(B11),"Január","Február","Marec","Apríl","Máj","Jún","Júl","August","September","Október","November","December")) | F11: =IF(B11="","",MONTH(B11)) | Q11: =IF(OR(B11="",B10=""),"",B11-B10) | S11: =IF(B11="","",IF(L11="Absolvovaný","Absolvovaný",IF(L11="Zrušený","Zrušený","Plánovaný"))) | T11: =IF(Q11="","",Q11/7)
C12: =IF(B12="","",YEAR(B12)) | D12: =IF(B12="","",CHOOSE(MONTH(B12),"Január","Február","Marec","Apríl","Máj","Jún","Júl","August","September","Október","November","December")) | F12: =IF(B12="","",MONTH(B12)) | Q12: =IF(OR(B12="",B11=""),"",B12-B11) | S12: =IF(B12="","",IF(L12="Absolvovaný","Absolvovaný",IF(L12="Zrušený","Zrušený","Plánovaný"))) | T12: =IF(Q12="","",Q12/7)
C13: =IF(B13="","",YEAR(B13)) | D13: =IF(B13="","",CHOOSE(MONTH(B13),"Január","Február","Marec","Apríl","Máj","Jún","Júl","August","September","Október","November","December")) | F13: =IF(B13="","",MONTH(B13)) | Q13: =IF(OR(B13="",B12=""),"",B13-B12) | S13: =IF(B13="","",IF(L13="Absolvovaný","Absolvovaný",IF(L13="Zrušený","Zrušený","Plánovaný"))) | T13: =IF(Q13="","",Q13/7)
C14: =IF(B14="","",YEAR(B14)) | D14: =IF(B14="","",CHOOSE(MONTH(B14),"Január","Február","Marec","Apríl","Máj","Jún","Júl","August","September","Október","November","December")) | F14: =IF(B14="","",MONTH(B14)) | Q14: =IF(OR(B14="",B13=""),"",B14-B13) | S14: =IF(B14="","",IF(L14="Absolvovaný","Absolvovaný",IF(L14="Zrušený","Zrušený","Plánovaný"))) | T14: =IF(Q14="","",Q14/7)
C15: =IF(B15="","",YEAR(B15)) | D15: =IF(B15="","",CHOOSE(MONTH(B15),"Január","Február","Marec","Apríl","Máj","Jún","Júl","August","September","Október","November","December")) | F15: =IF(B15="","",MONTH(B15)) | Q15: =IF(OR(B15="",B14=""),"",B15-B14) | S15: =IF(B15="","",IF(L15="Absolvovaný","Absolvovaný",IF(L15="Zrušený","Zrušený","Plánovaný"))) | T15: =IF(Q15="","",Q15/7)
C16: =IF(B16="","",YEAR(B16)) | D16: =IF(B16="","",CHOOSE(MONTH(B16),"Január","Február","Marec","Apríl","Máj","Jún","Júl","August","September","Október","November","December")) | F16: =IF(B16="","",MONTH(B16)) | Q16: =IF(OR(B16="",B15=""),"",B16-B15) | S16: =IF(B16="","",IF(L16="Absolvovaný","Absolvovaný",IF(L16="Zrušený","Zrušený","Plánovaný"))) | T16: =IF(Q16="","",Q16/7)
... C200: =IF(B200="","",YEAR(B200)) | D200: =IF(B200="","",CHOOSE(MONTH(B200),"Január","Február","Marec","Apríl","Máj","Jún","Júl","August","September","Október","November","December")) | F200: =IF(B200="","",MONTH(B200)) | Q200: =IF(OR(B200="",B199=""),"",B200-B199) | S200: =IF(B200="","",IF(L200="Absolvovaný","Absolvovaný",IF(L200="Zrušený","Zrušený","Plánovaný"))) | T200: =IF(Q200="","",Q200/7)

Sheet Zoznamy
A1: Typ | B1: Priorita | C1: Stav | D1: Registrácia
A2: Cesta | B2: A | C2: Zvažujem | D2: Nie
A3: Trail | B3: B | C3: Plánujem | D3: Otvorená
A4: Kros | B4: C | C4: Registrovaný | D4: Hotová
A5: Dráha | C5: Absolvovaný
A6: Iné | C6: Zrušený

Sheet Dashboard
A1: BEŽECKÉ PRETEKY 2027 | J1: Najbližší_dátumčas | K1: Kandidát
J2: =IF(COUNT(K2:K200)=0,"",MIN(K2:K200)) -> 46495.417 | K2: =IF(AND(Preteky_2027!B2<>"",Preteky_2027!B2+Preteky_2027!E2>NOW(),Preteky_2027!L2<>"Zrušený"),Preteky_2027!B2+Preteky_2027!E2,"") -> 46495.417
J3: =IF(J2="","",MATCH(INT(J2),Preteky_2027!$B$2:$B$200,0)) -> 1 | K3: =IF(AND(Preteky_2027!B3<>"",Preteky_2027!B3+Preteky_2027!E3>NOW(),Preteky_2027!L3<>"Zrušený"),Preteky_2027!B3+Preteky_2027!E3,"") -> 46557.75
A4: Najbližší pretek | E4: Zostávajúci čas | J4: =IF(J2="","",MOD(J2,1)) -> 0.41666667 | K4: =IF(AND(Preteky_2027!B4<>"",Preteky_2027!B4+Preteky_2027!E4>NOW(),Preteky_2027!L4<>"Zrušený"),Preteky_2027!B4+Preteky_2027!E4,"") -> 46663.375
A5: =IF($J$3="","Žiadny budúci pretek",INDEX(Preteky_2027!$G$2:$G$200,$J$3)) -> Generali 1/2Maraton Praha 2027 | E5: =IF($J$5="","000 : 00 : 00 : 00",TEXT(INT(MAX(0,$J$5-NOW())),"000")&" : "&TEXT(INT(MOD(MAX(0,$J$5-NOW())*24,24)),"00")&" : "&TEXT(INT(MOD(MAX(0,$J$5-NOW())*1440,60)),"00")&" : "&TEXT(INT(MOD(MAX(0,$J$5-NOW())*86400,60)),"00")) -> 198 : 20 : 14 : 14 | J5: =J2 -> 46495.417 | K5: =IF(AND(Preteky_2027!B5<>"",Preteky_2027!B5+Preteky_2027!E5>NOW(),Preteky_2027!L5<>"Zrušený"),Preteky_2027!B5+Preteky_2027!E5,"")
A6: =IF($J$5="","",$J$5) -> 46495.417 | K6: =IF(AND(Preteky_2027!B6<>"",Preteky_2027!B6+Preteky_2027!E6>NOW(),Preteky_2027!L6<>"Zrušený"),Preteky_2027!B6+Preteky_2027!E6,"")
K7: =IF(AND(Preteky_2027!B7<>"",Preteky_2027!B7+Preteky_2027!E7>NOW(),Preteky_2027!L7<>"Zrušený"),Preteky_2027!B7+Preteky_2027!E7,"")
A8: Počet pretekov | C8: A-preteky | E8: Celková vzdialenosť | G8: Registrované | K8: =IF(AND(Preteky_2027!B8<>"",Preteky_2027!B8+Preteky_2027!E8>NOW(),Preteky_2027!L8<>"Zrušený"),Preteky_2027!B8+Preteky_2027!E8,"")
A9: =COUNT(Preteky_2027!$B$2:$B$200) -> 3 | C9: =COUNTIF(Preteky_2027!$K$2:$K$200,"A") -> 2 | E9: =SUM(Preteky_2027!$J$2:$J$200) -> 71 | G9: =COUNTIF(Preteky_2027!$L$2:$L$200,"Registrovaný") -> 0 | K9: =IF(AND(Preteky_2027!B9<>"",Preteky_2027!B9+Preteky_2027!E9>NOW(),Preteky_2027!L9<>"Zrušený"),Preteky_2027!B9+Preteky_2027!E9,"")
K10: =IF(AND(Preteky_2027!B10<>"",Preteky_2027!B10+Preteky_2027!E10>NOW(),Preteky_2027!L10<>"Zrušený"),Preteky_2027!B10+Preteky_2027!E10,"")
K11: =IF(AND(Preteky_2027!B11<>"",Preteky_2027!B11+Preteky_2027!E11>NOW(),Preteky_2027!L11<>"Zrušený"),Preteky_2027!B11+Preteky_2027!E11,"")
K12: =IF(AND(Preteky_2027!B12<>"",Preteky_2027!B12+Preteky_2027!E12>NOW(),Preteky_2027!L12<>"Zrušený"),Preteky_2027!B12+Preteky_2027!E12,"")
A13: Mini kalendár sezóny | K13: =IF(AND(Preteky_2027!B13<>"",Preteky_2027!B13+Preteky_2027!E13>NOW(),Preteky_2027!L13<>"Zrušený"),Preteky_2027!B13+Preteky_2027!E13,"")
A14: Jan | B14: Feb | C14: Mar | D14: Apr | E14: Máj | F14: Jún | G14: Júl | H14: Aug | K14: =IF(AND(Preteky_2027!B14<>"",Preteky_2027!B14+Preteky_2027!E14>NOW(),Preteky_2027!L14<>"Zrušený"),Preteky_2027!B14+Preteky_2027!E14,"")
A15: =COUNTIF(Preteky_2027!$F$2:$F$200,1) -> 0 | B15: =COUNTIF(Preteky_2027!$F$2:$F$200,2) -> 0 | C15: =COUNTIF(Preteky_2027!$F$2:$F$200,3) -> 0 | D15: =COUNTIF(Preteky_2027!$F$2:$F$200,4) -> 1 | E15: =COUNTIF(Preteky_2027!$F$2:$F$200,5) -> 0 | F15: =COUNTIF(Preteky_2027!$F$2:$F$200,6) -> 1 | G15: =COUNTIF(Preteky_2027!$F$2:$F$200,7) -> 0 | H15: =COUNTIF(Preteky_2027!$F$2:$F$200,8) -> 0 | K15: =IF(AND(Preteky_2027!B15<>"",Preteky_2027!B15+Preteky_2027!E15>NOW(),Preteky_2027!L15<>"Zrušený"),Preteky_2027!B15+Preteky_2027!E15,"")
K16: =IF(AND(Preteky_2027!B16<>"",Preteky_2027!B16+Preteky_2027!E16>NOW(),Preteky_2027!L16<>"Zrušený"),Preteky_2027!B16+Preteky_2027!E16,"")
A17: Sep | B17: Okt | C17: Nov | D17: Dec | K17: =IF(AND(Preteky_2027!B17<>"",Preteky_2027!B17+Preteky_2027!E17>NOW(),Preteky_2027!L17<>"Zrušený"),Preteky_2027!B17+Preteky_2027!E17,"")
A18: =COUNTIF(Preteky_2027!$F$2:$F$200,9) -> 0 | B18: =COUNTIF(Preteky_2027!$F$2:$F$200,10) -> 1 | C18: =COUNTIF(Preteky_2027!$F$2:$F$200,11) -> 0 | D18: =COUNTIF(Preteky_2027!$F$2:$F$200,12) -> 0 | K18: =IF(AND(Preteky_2027!B18<>"",Preteky_2027!B18+Preteky_2027!E18>NOW(),Preteky_2027!L18<>"Zrušený"),Preteky_2027!B18+Preteky_2027!E18,"")
K19: =IF(AND(Preteky_2027!B19<>"",Preteky_2027!B19+Preteky_2027!E19>NOW(),Preteky_2027!L19<>"Zrušený"),Preteky_2027!B19+Preteky_2027!E19,"")
A20: Stav sezóny | K20: =IF(AND(Preteky_2027!B20<>"",Preteky_2027!B20+Preteky_2027!E20>NOW(),Preteky_2027!L20<>"Zrušený"),Preteky_2027!B20+Preteky_2027!E20,"")
K21: =IF(AND(Preteky_2027!B21<>"",Preteky_2027!B21+Preteky_2027!E21>NOW(),Preteky_2027!L21<>"Zrušený"),Preteky_2027!B21+Preteky_2027!E21,"")
A22: Plánované preteky | E22: Absolvované preteky | K22: =IF(AND(Preteky_2027!B22<>"",Preteky_2027!B22+Preteky_2027!E22>NOW(),Preteky_2027!L22<>"Zrušený"),Preteky_2027!B22+Preteky_2027!E22,"")
A23: =COUNTIF(Preteky_2027!$S$2:$S$200,"Plánovaný") -> 3 | E23: =COUNTIF(Preteky_2027!$S$2:$S$200,"Absolvovaný") -> 0 | K23: =IF(AND(Preteky_2027!B23<>"",Preteky_2027!B23+Preteky_2027!E23>NOW(),Preteky_2027!L23<>"Zrušený"),Preteky_2027!B23+Preteky_2027!E23,"")
K24: =IF(AND(Preteky_2027!B24<>"",Preteky_2027!B24+Preteky_2027!E24>NOW(),Preteky_2027!L24<>"Zrušený"),Preteky_2027!B24+Preteky_2027!E24,"")
K25: =IF(AND(Preteky_2027!B25<>"",Preteky_2027!B25+Preteky_2027!E25>NOW(),Preteky_2027!L25<>"Zrušený"),Preteky_2027!B25+Preteky_2027!E25,"")
K26: =IF(AND(Preteky_2027!B26<>"",Preteky_2027!B26+Preteky_2027!E26>NOW(),Preteky_2027!L26<>"Zrušený"),Preteky_2027!B26+Preteky_2027!E26,"")
A27: Časová os pretekov a rozostupy | K27: =IF(AND(Preteky_2027!B27<>"",Preteky_2027!B27+Preteky_2027!E27>NOW(),Preteky_2027!L27<>"Zrušený"),Preteky_2027!B27+Preteky_2027!E27,"")
A28: Dátum | B28: Preteky | C28: Miesto | D28: km | E28: Priorita | F28: Stav | G28: Odstup dní | H28: Odstup týždne | K28: =IF(AND(Preteky_2027!B28<>"",Preteky_2027!B28+Preteky_2027!E28>NOW(),Preteky_2027!L28<>"Zrušený"),Preteky_2027!B28+Preteky_2027!E28,"")
A29: =IF(Preteky_2027!B2="","",Preteky_2027!B2) -> 46495 | B29: =IF(Preteky_2027!G2="","",Preteky_2027!G2) -> Generali 1/2Maraton Praha 2027 | C29: =IF(Preteky_2027!H2="","",Preteky_2027!H2) -> Praha | D29: =IF(Preteky_2027!J2="","",Preteky_2027!J2) -> 21 | E29: =IF(Preteky_2027!K2="","",Preteky_2027!K2) -> A | F29: =IF(Preteky_2027!L2="","",Preteky_2027!L2) -> Plánujem | G29: =IF(Preteky_2027!Q2="","",Preteky_2027!Q2) | H29: =IF(Preteky_2027!T2="","",Preteky_2027!T2) | K29: =IF(AND(Preteky_2027!B29<>"",Preteky_2027!B29+Preteky_2027!E29>NOW(),Preteky_2027!L29<>"Zrušený"),Preteky_2027!B29+Preteky_2027!E29,"")
A30: =IF(Preteky_2027!B3="","",Preteky_2027!B3) -> 46557 | B30: =IF(Preteky_2027!G3="","",Preteky_2027!G3) -> G-Schock Runday Trávnica | C30: =IF(Preteky_2027!H3="","",Preteky_2027!H3) -> Trávnica | D30: =IF(Preteky_2027!J3="","",Preteky_2027!J3) -> 8 | E30: =IF(Preteky_2027!K3="","",Preteky_2027!K3) -> B | F30: =IF(Preteky_2027!L3="","",Preteky_2027!L3) -> Plánujem | G30: =IF(Preteky_2027!Q3="","",Preteky_2027!Q3) -> 62 | H30: =IF(Preteky_2027!T3="","",Preteky_2027!T3) -> 8.8571429 | K30: =IF(AND(Preteky_2027!B30<>"",Preteky_2027!B30+Preteky_2027!E30>NOW(),Preteky_2027!L30<>"Zrušený"),Preteky_2027!B30+Preteky_2027!E30,"")
A31: =IF(Preteky_2027!B4="","",Preteky_2027!B4) -> 46663 | B31: =IF(Preteky_2027!G4="","",Preteky_2027!G4) -> Košice Peace Marathon | C31: =IF(Preteky_2027!H4="","",Preteky_2027!H4) -> Košice | D31: =IF(Preteky_2027!J4="","",Preteky_2027!J4) -> 42 | E31: =IF(Preteky_2027!K4="","",Preteky_2027!K4) -> A | F31: =IF(Preteky_2027!L4="","",Preteky_2027!L4) -> Plánujem | G31: =IF(Preteky_2027!Q4="","",Preteky_2027!Q4) -> 106 | H31: =IF(Preteky_2027!T4="","",Preteky_2027!T4) -> 15.142857 | K31: =IF(AND(Preteky_2027!B31<>"",Preteky_2027!B31+Preteky_2027!E31>NOW(),Preteky_2027!L31<>"Zrušený"),Preteky_2027!B31+Preteky_2027!E31,"")
A32: =IF(Preteky_2027!B5="","",Preteky_2027!B5) | B32: =IF(Preteky_2027!G5="","",Preteky_2027!G5) | C32: =IF(Preteky_2027!H5="","",Preteky_2027!H5) | D32: =IF(Preteky_2027!J5="","",Preteky_2027!J5) | E32: =IF(Preteky_2027!K5="","",Preteky_2027!K5) | F32: =IF(Preteky_2027!L5="","",Preteky_2027!L5) | G32: =IF(Preteky_2027!Q5="","",Preteky_2027!Q5) | H32: =IF(Preteky_2027!T5="","",Preteky_2027!T5) | K32: =IF(AND(Preteky_2027!B32<>"",Preteky_2027!B32+Preteky_2027!E32>NOW(),Preteky_2027!L32<>"Zrušený"),Preteky_2027!B32+Preteky_2027!E32,"")
A33: =IF(Preteky_2027!B6="","",Preteky_2027!B6) | B33: =IF(Preteky_2027!G6="","",Preteky_2027!G6) | C33: =IF(Preteky_2027!H6="","",Preteky_2027!H6) | D33: =IF(Preteky_2027!J6="","",Preteky_2027!J6) | E33: =IF(Preteky_2027!K6="","",Preteky_2027!K6) | F33: =IF(Preteky_2027!L6="","",Preteky_2027!L6) | G33: =IF(Preteky_2027!Q6="","",Preteky_2027!Q6) | H33: =IF(Preteky_2027!T6="","",Preteky_2027!T6) | K33: =IF(AND(Preteky_2027!B33<>"",Preteky_2027!B33+Preteky_2027!E33>NOW(),Preteky_2027!L33<>"Zrušený"),Preteky_2027!B33+Preteky_2027!E33,"")
A34: =IF(Preteky_2027!B7="","",Preteky_2027!B7) | B34: =IF(Preteky_2027!G7="","",Preteky_2027!G7) | C34: =IF(Preteky_2027!H7="","",Preteky_2027!H7) | D34: =IF(Preteky_2027!J7="","",Preteky_2027!J7) | E34: =IF(Preteky_2027!K7="","",Preteky_2027!K7) | F34: =IF(Preteky_2027!L7="","",Preteky_2027!L7) | G34: =IF(Preteky_2027!Q7="","",Preteky_2027!Q7) | H34: =IF(Preteky_2027!T7="","",Preteky_2027!T7) | K34: =IF(AND(Preteky_2027!B34<>"",Preteky_2027!B34+Preteky_2027!E34>NOW(),Preteky_2027!L34<>"Zrušený"),Preteky_2027!B34+Preteky_2027!E34,"")
A35: =IF(Preteky_2027!B8="","",Preteky_2027!B8) | B35: =IF(Preteky_2027!G8="","",Preteky_2027!G8) | C35: =IF(Preteky_2027!H8="","",Preteky_2027!H8) | D35: =IF(Preteky_2027!J8="","",Preteky_2027!J8) | E35: =IF(Preteky_2027!K8="","",Preteky_2027!K8) | F35: =IF(Preteky_2027!L8="","",Preteky_2027!L8) | G35: =IF(Preteky_2027!Q8="","",Preteky_2027!Q8) | H35: =IF(Preteky_2027!T8="","",Preteky_2027!T8) | K35: =IF(AND(Preteky_2027!B35<>"",Preteky_2027!B35+Preteky_2027!E35>NOW(),Preteky_2027!L35<>"Zrušený"),Preteky_2027!B35+Preteky_2027!E35,"")
A36: =IF(Preteky_2027!B9="","",Preteky_2027!B9) | B36: =IF(Preteky_2027!G9="","",Preteky_2027!G9) | C36: =IF(Preteky_2027!H9="","",Preteky_2027!H9) | D36: =IF(Preteky_2027!J9="","",Preteky_2027!J9) | E36: =IF(Preteky_2027!K9="","",Preteky_2027!K9) | F36: =IF(Preteky_2027!L9="","",Preteky_2027!L9) | G36: =IF(Preteky_2027!Q9="","",Preteky_2027!Q9) | H36: =IF(Preteky_2027!T9="","",Preteky_2027!T9) | K36: =IF(AND(Preteky_2027!B36<>"",Preteky_2027!B36+Preteky_2027!E36>NOW(),Preteky_2027!L36<>"Zrušený"),Preteky_2027!B36+Preteky_2027!E36,"")
A37: =IF(Preteky_2027!B10="","",Preteky_2027!B10) | B37: =IF(Preteky_2027!G10="","",Preteky_2027!G10) | C37: =IF(Preteky_2027!H10="","",Preteky_2027!H10) | D37: =IF(Preteky_2027!J10="","",Preteky_2027!J10) | E37: =IF(Preteky_2027!K10="","",Preteky_2027!K10) | F37: =IF(Preteky_2027!L10="","",Preteky_2027!L10) | G37: =IF(Preteky_2027!Q10="","",Preteky_2027!Q10) | H37: =IF(Preteky_2027!T10="","",Preteky_2027!T10) | K37: =IF(AND(Preteky_2027!B37<>"",Preteky_2027!B37+Preteky_2027!E37>NOW(),Preteky_2027!L37<>"Zrušený"),Preteky_2027!B37+Preteky_2027!E37,"")
A38: =IF(Preteky_2027!B11="","",Preteky_2027!B11) | B38: =IF(Preteky_2027!G11="","",Preteky_2027!G11) | C38: =IF(Preteky_2027!H11="","",Preteky_2027!H11) | D38: =IF(Preteky_2027!J11="","",Preteky_2027!J11) | E38: =IF(Preteky_2027!K11="","",Preteky_2027!K11) | F38: =IF(Preteky_2027!L11="","",Preteky_2027!L11) | G38: =IF(Preteky_2027!Q11="","",Preteky_2027!Q11) | H38: =IF(Preteky_2027!T11="","",Preteky_2027!T11) | K38: =IF(AND(Preteky_2027!B38<>"",Preteky_2027!B38+Preteky_2027!E38>NOW(),Preteky_2027!L38<>"Zrušený"),Preteky_2027!B38+Preteky_2027!E38,"")
A39: =IF(Preteky_2027!B12="","",Preteky_2027!B12) | B39: =IF(Preteky_2027!G12="","",Preteky_2027!G12) | C39: =IF(Preteky_2027!H12="","",Preteky_2027!H12) | D39: =IF(Preteky_2027!J12="","",Preteky_2027!J12) | E39: =IF(Preteky_2027!K12="","",Preteky_2027!K12) | F39: =IF(Preteky_2027!L12="","",Preteky_2027!L12) | G39: =IF(Preteky_2027!Q12="","",Preteky_2027!Q12) | H39: =IF(Preteky_2027!T12="","",Preteky_2027!T12) | K39: =IF(AND(Preteky_2027!B39<>"",Preteky_2027!B39+Preteky_2027!E39>NOW(),Preteky_2027!L39<>"Zrušený"),Preteky_2027!B39+Preteky_2027!E39,"")
A40: =IF(Preteky_2027!B13="","",Preteky_2027!B13) | B40: =IF(Preteky_2027!G13="","",Preteky_2027!G13) | C40: =IF(Preteky_2027!H13="","",Preteky_2027!H13) | D40: =IF(Preteky_2027!J13="","",Preteky_2027!J13) | E40: =IF(Preteky_2027!K13="","",Preteky_2027!K13) | F40: =IF(Preteky_2027!L13="","",Preteky_2027!L13) | G40: =IF(Preteky_2027!Q13="","",Preteky_2027!Q13) | H40: =IF(Preteky_2027!T13="","",Preteky_2027!T13) | K40: =IF(AND(Preteky_2027!B40<>"",Preteky_2027!B40+Preteky_2027!E40>NOW(),Preteky_2027!L40<>"Zrušený"),Preteky_2027!B40+Preteky_2027!E40,"")
...
